Workbook

Sheet Legend
A1: Evidentiary Audit Coding Workbook
A3: Sheets
A4: Articles | B4: One row per included article. Screening decision, positioning (P1–P4), citation data.
A5: Claims | B5: One row per extracted claim. Yellow cells are coder inputs; Fit is computed from the matrix and reviewed.
A6: Canonical_Claims | B6: Frozen list of canonical claims built in the pilot. Claims sheet references these IDs.
A7: Fit_Matrix | B7: Lookup table: claim type × primary warrant × positioning → fit. Edit only via the change log.
A8: Change_Log | B8: Every protocol change with date, reason, stage.
A9: Summary | B9: Live counts by claim type, warrant, fit, indicators. Formulas only.
A11: Conventions
A12: Yellow fill | B12: Coder enters a value (dropdowns where available).
A13: Grey header | B13: Do not edit.
A14: Row 2 in Claims/Articles | B14: Example row with realistic values; delete before real coding.
A16: Codes
A17: Claim type | B17: descriptive | conceptual | causal | predictive | normative | other
A18: Warrant | B18: W1 orig quant | W2 orig qual | W3 secondary | W4 analogy | W5 deduction | W6 authority | W7 declared conjecture | W8 none
A19: W3 sub-code | B19: to_W1W2 | to_W3 | to_W4W8 | unknown
A20: Positioning | B20: P1 neo-positivist | P2 interpretivist | P3 critical | P4 theory-building/policy
A21: Fit | B21: adequate | partial | inadequate. fit_final: copy fit_computed unless you override; an override requires override_reason.
A22: Indicators | B22: 1 = present, 0 = absent, NA = not a predictive/causal-future claim
A23: Valence | B23: supporting | neutral | critical (only for W3 claims)
A25: Columns added 2026-09-10
A26: w4_developed | B26: 1 = the analogy is developed over at least one full section; 0 = not; NA = rule does not apply. Read by the fit formula for predictive+W4 under P2/P3/P4.
A27: orig_scope_conditions | B27: Same three indicators, recorded for the ORIGINATING text of a W3 claim. Needed for Table 4, RQ3 and H2. unknown = source not retrievable.
A28: orig_conjectural_status | B28: See orig_scope_conditions.
A29: orig_falsifier | B29: See orig_scope_conditions.
A30: w3_source_peer_reviewed | B30: 1 = cited source is peer reviewed; 0 = grey. Recorded separately from the W3 sub-code, which turns on whether the source carries data.
A31: secondary_claim_type | B31: For a claim that is both causal and predictive (Appendix A.3). claim_type holds the primary; distributions are reported on the primary only.
A32: p4_causal_flag | B32: Derived. Marks causal claims in P4 articles so they can be tabulated separately.
A33: Indicator storage | B33: scope/conjectural/falsifier are NUMBERS 1 and 0, or the text NA. Do not type them as text; the fit formula tests both forms but the analysis script expects numbers.

Sheet Fit_Matrix
A1: key | B1: fit | C1: note
A2: P1|descriptive|W1 | B2: adequate
A3: P1|descriptive|W2 | B3: adequate
A4: P1|descriptive|W3_to_W1W2 | B4: adequate
A5: P1|descriptive|W3_to_W3 | B5: partial
A6: P1|descriptive|W3_to_W4W8 | B6: partial
A7: P1|descriptive|W3_unknown | B7: partial
A8: P1|descriptive|W4 | B8: partial
A9: P1|descriptive|W5 | B9: inadequate
A10: P1|descriptive|W6 | B10: partial
A11: P1|descriptive|W7 | B11: partial
A12: P1|descriptive|W8 | B12: inadequate
A13: P1|conceptual|W1 | B13: adequate
... A32: P1|causal|W6 | B32: inadequate
A33: P1|causal|W7 | B33: partial | C33: adequate only if all three indicators = 1; else partial (see Claims formula)
A34: P1|causal|W8 | B34: inadequate
A35: P1|predictive|W1 | B35: adequate
A36: P1|predictive|W2 | B36: adequate
A37: P1|predictive|W3_to_W1W2 | B37: adequate
A38: P1|predictive|W3_to_W3 | B38: partial
A39: P1|predictive|W3_to_W4W8 | B39: partial
A40: P1|predictive|W3_unknown | B40: partial
A41: P1|predictive|W4 | B41: partial
A42: P1|predictive|W5 | B42: partial
A43: P1|predictive|W6 | B43: partial
A44: P1|predictive|W7 | B44: adequate | C44: adequate only if all three indicators = 1; else partial (see Claims formula)
A45: P1|predictive|W8 | B45: inadequate
A46: P1|normative|W1 | B46: adequate
A47: P1|normative|W2 | B47: adequate
A48: P1|normative|W3_to_W1W2 | B48: adequate
A49: P1|normative|W3_to_W3 | B49: partial
A50: P1|normative|W3_to_W4W8 | B50: partial
A51: P1|normative|W3_unknown | B51: partial
A52: P1|normative|W4 | B52: partial
A53: P1|normative|W5 | B53: partial
A54: P1|normative|W6 | B54: partial
A55: P1|normative|W7 | B55: partial
A56: P1|normative|W8 | B56: inadequate
... A90: P2|causal|W1 | B90: adequate
A91: P2|causal|W2 | B91: adequate | C91: P2/P3: constitutive causal claim, documented practice suffices
...

Sheet Canonical_Claims
A1: claim_id | B1: canonical_statement | C1: claim_family | D1: added_in_pilot_date | E1: notes
A2: C001 | B2: Organisational adoption capacity, not access to algorithms, determines which states field military AI first | C2: diffusion and adoption
A3: C002 | B3: AI-generated assessments compress crisis decision time and raise escalation risk | C3: crisis decision-making
A4: C003 | B4: AI-enabled sensing degrades the survivability of second-strike nuclear forces | C4: strategic stability
A5: C004 | B5: Autonomous weapons systems reshape norms of use through practice rather than deliberate regulation | C5: norms, agency, critique
A6: C005 | B6: AI is a strategic asset over which great powers will compete | C6: balance of power / geoeconomics
A7: C006 | B7: Uneven AI adoption capacity creates 'haves' and 'have-nots' inside alliances, straining burden-sharing and interoperability | C7: alliances | D7: pilot 2026-09-07 | E7: from Lin-Greenberg 2020
A8: C007 | B8: Commercially driven, dual-use AI diffuses rapidly and erodes first-mover advantage; militarily exclusive AI does the reverse | C8: diffusion and adoption | D8: pilot 2026-09-07 | E8: from Horowitz 2018; two-scenario form
A9: C008 | B9: Adversaries can use AI-enabled deception and data poisoning to disrupt command and control and trust | C9: strategic stability / alliances | D9: pilot 2026-09-07 | E9: from Lin-Greenberg 2020

Sheet Articles
A1: article_id | B1: author_year | C1: title | D1: journal | E1: year | F1: db_source | G1: screen_title_abstract | H1: screen_fulltext | I1: exclusion_reason | J1: positioning | K1: positioning_inferred | L1: citations_raw | M1: citation_date | N1: citations_per_year | O1: double_coded | P1: coder_A | Q1: coder_B | R1: notes
A2: A002 | B2: Horowitz 2018 | C2: Artificial Intelligence, International Competition, and the Balance of Power | D2: Texas National Security Review | E2: 2018 | F2: pilot/open access | G2: include | H2: include | J2: P4 | K2: yes | N2: =IF(L2="","",IF(2026-E2>0,L2/(2026-E2),L2)) | O2: no | P2: CL | R2: PILOT: open-access full text; author states 'initial framework'; positioning inferred. Check TNSR indexing in WoS/Scopus before corpus inclusion.
A3: A003 | B3: Lin-Greenberg 2020 | C3: Allies and Artificial Intelligence: Obstacles to Operations and Decision-Making | D3: Texas National Security Review | E3: 2020 | F3: pilot/open access | G3: include | H3: include | J3: P4 | K3: no | N3: =IF(L3="","",IF(2026-E3>0,L3/(2026-E3),L3)) | O3: no | P3: CL | R3: PILOT: author states article 'offers a framework for future hypothesis testing' (explicit P4). Check TNSR indexing.
N4: =IF(L4="","",IF(2026-E4>0,L4/(2026-E4),L4))
N5: =IF(L5="","",IF(2026-E5>0,L5/(2026-E5),L5))
N6: =IF(L6="","",IF(2026-E6>0,L6/(2026-E6),L6))
N7: =IF(L7="","",IF(2026-E7>0,L7/(2026-E7),L7))
N8: =IF(L8="","",IF(2026-E8>0,L8/(2026-E8),L8))
N9: =IF(L9="","",IF(2026-E9>0,L9/(2026-E9),L9))
N10: =IF(L10="","",IF(2026-E10>0,L10/(2026-E10),L10))
N11: =IF(L11="","",IF(2026-E11>0,L11/(2026-E11),L11))
N12: =IF(L12="","",IF(2026-E12>0,L12/(2026-E12),L12))
N13: =IF(L13="","",IF(2026-E13>0,L13/(2026-E13),L13))
N14: =IF(L14="","",IF(2026-E14>0,L14/(2026-E14),L14))
N15: =IF(L15="","",IF(2026-E15>0,L15/(2026-E15),L15))
... N2000: =IF(L2000="","",IF(2026-E2000>0,L2000/(2026-E2000),L2000))

Sheet Claims
A1: claim_id | B1: article_id | C1: coder | D1: location | E1: claim_text | F1: claim_type | G1: warrants_present | H1: primary_warrant | I1: w3_subcode | J1: positioning | K1: scope_conditions | L1: conjectural_status | M1: falsifier | N1: canonical_claim_id | O1: citation_valence | P1: fit_key | Q1: fit_computed | R1: fit_final | S1: override_reason | T1: notes | U1: w4_developed | V1: orig_scope_conditions | W1: orig_conjectural_status | X1: orig_falsifier | Y1: w3_source_peer_reviewed | Z1: secondary_claim_type | AA1: p4_causal_flag
A2: K0001 | B2: A002 | C2: CL | D2: abstract | E2: AI more closely resembles enabling technologies such as the combustion engine or electricity than a specific weapon | F2: conceptual | G2: W4;W5 | H2: W4 | J2: P4 | K2: NA | L2: NA | M2: NA | P2: =IF(OR(F2="",H2="",J2=""),"",J2&"|"&F2&"|"&IF(H2="W3","W3_"&IF(I2="","unknown",I2),H2)) -> P4|conceptual|W4 | Q2: =IF(P2="","",IFERROR(IF(AND(H2="W7",OR(F2="causal",F2="predictive")),IF(AND(OR(K2=1,K2="1"),OR(L2=1,L2="1"),OR(M2=1,M2="1")),"adequate","partial"),IF(AND(H2="W4",F2="predictive",OR(J2="P2",J2="P3",J2="P4")),IF(OR(U2=1,U2="1"),"adequate","partial"),INDEX(Fit_Matrix!$B:$B,MATCH(P2,Fit_Matrix!$A:$A,0)))),"CHECK KEY")) -> adequate | R2: adequate | T2: developed analogy (full subsection 'AI Is an Enabler') | U2: NA | V2: NA | W2: NA | X2: NA | Y2: NA | Z2: NA | AA2: =IF(A2="","",IF(AND(J2="P4",F2="causal"),"P4-CAUSAL",""))
A3: K0002 | B3: A002 | C3: CL | D3: introduction | E3: If commercially driven AI fuels innovation and military algorithms are close to civilian ones, AI will diffuse rapidly to militaries, limiting first-mover advantages | F3: predictive | G3: W5;W4;W7 | H3: W7 | J3: P4 | K3: 1 | L3: 1 | M3: 0 | N3: C007 | P3: =IF(OR(F3="",H3="",J3=""),"",J3&"|"&F3&"|"&IF(H3="W3","W3_"&IF(I3="","unknown",I3),H3)) -> P4|predictive|W7 | Q3: =IF(P3="","",IFERROR(IF(AND(H3="W7",OR(F3="causal",F3="predictive")),IF(AND(OR(K3=1,K3="1"),OR(L3=1,L3="1"),OR(M3=1,M3="1")),"adequate","partial"),IF(AND(H3="W4",F3="predictive",OR(J3="P2",J3="P3",J3="P4")),IF(OR(U3=1,U3="1"),"adequate","partial"),INDEX(Fit_Matrix!$B:$B,MATCH(P3,Fit_Matrix!$A:$A,0)))),"CHECK KEY")) -> partial | R3: partial | T3: explicit scenario framing ('explores the possibility'); scope stated; no falsifier named. Codebook note: scenario-conditional claims land at partial under current rule | U3: NA | V3: NA | W3: NA | X3: NA | Y3: NA | Z3: NA | AA3: =IF(A3="","",IF(AND(J3="P4",F3="causal"),"P4-CAUSAL",""))
A4: K0003 | B4: A002 | C4: CL | D4: introduction | E4: Military AI based more exclusively in defence research will generate larger first-mover advantages for early adopters | F4: predictive | G4: W5;W4;W7 | H4: W7 | J4: P4 | K4: 1 | L4: 1 | M4: 0 | N4: C007 | P4: =IF(OR(F4="",H4="",J4=""),"",J4&"|"&F4&"|"&IF(H4="W3","W3_"&IF(I4="","unknown",I4),H4)) -> P4|predictive|W7 | Q4: =IF(P4="","",IFERROR(IF(AND(H4="W7",OR(F4="causal",F4="predictive")),IF(AND(OR(K4=1,K4="1"),OR(L4=1,L4="1"),OR(M4=1,M4="1")),"adequate","partial"),IF(AND(H4="W4",F4="predictive",OR(J4="P2",J4="P3",J4="P4")),IF(OR(U4=1,U4="1"),"adequate","partial"),INDEX(Fit_Matrix!$B:$B,MATCH(P4,Fit_Matrix!$A:$A,0)))),"CHECK KEY")) -> partial | R4: partial | T4: second scenario; 'it is plausible that' | U4: NA | V4: NA | W4: NA | X4: NA | Y4: NA | Z4: NA | AA4: =IF(A4="","",IF(AND(J4="P4",F4="causal"),"P4-CAUSAL",""))
A5: K0004 | B5: A002 | C5: CL | D5: body (Technology and BoP) | E5: The impact of technological change on global politics depends more on how organisations adopt and use capabilities than on the technology itself | F5: causal | G5: W3;W4 | H5: W3 | I5: to_W1W2 | J5: P4 | K5: NA | L5: NA | M5: NA | N5: C001 | O5: supporting | P5: =IF(OR(F5="",H5="",J5=""),"",J5&"|"&F5&"|"&IF(H5="W3","W3_"&IF(I5="","unknown",I5),H5)) -> P4|causal|W3_to_W1W2 | Q5: =IF(P5="","",IFERROR(IF(AND(H5="W7",OR(F5="causal",F5="predictive")),IF(AND(OR(K5=1,K5="1"),OR(L5=1,L5="1"),OR(M5=1,M5="1")),"adequate","partial"),IF(AND(H5="W4",F5="predictive",OR(J5="P2",J5="P3",J5="P4")),IF(OR(U5=1,U5="1"),"adequate","partial"),INDEX(Fit_Matrix!$B:$B,MATCH(P5,Fit_Matrix!$A:$A,0)))),"CHECK KEY")) -> adequate | R5: adequate | T5: cites Posen, Rosen, Horowitz 2010 (case-based W2); P4 causal flagged | U5: NA | V5: NA | W5: NA | X5: NA | Y5: 1 | Z5: NA | AA5: =IF(A5="","",IF(AND(J5="P4",F5="causal"),"P4-CAUSAL","")) -> P4-CAUSAL
A6: K0005 | B6: A002 | C6: CL | D6: body | E6: No applications of AI have yet been used in ways that would count as a military innovation | F6: descriptive | G6: W6 | H6: W6 | J6: P4 | K6: NA | L6: NA | M6: NA | P6: =IF(OR(F6="",H6="",J6=""),"",J6&"|"&F6&"|"&IF(H6="W3","W3_"&IF(I6="","unknown",I6),H6)) -> P4|descriptive|W6 | Q6: =IF(P6="","",IFERROR(IF(AND(H6="W7",OR(F6="causal",F6="predictive")),IF(AND(OR(K6=1,K6="1"),OR(L6=1,L6="1"),OR(M6=1,M6="1")),"adequate","partial"),IF(AND(H6="W4",F6="predictive",OR(J6="P2",J6="P3",J6="P4")),IF(OR(U6=1,U6="1"),"adequate","partial"),INDEX(Fit_Matrix!$B:$B,MATCH(P6,Fit_Matrix!$A:$A,0)))),"CHECK KEY")) -> partial | R6: partial | T6: warrant is Cummings (Chatham House report), expert judgment | U6: NA | V6: NA | W6: NA | X6: NA | Y6: NA | Z6: NA | AA6: =IF(A6="","",IF(AND(J6="P4",F6="causal"),"P4-CAUSAL",""))
A7: K0006 | B7: A002 | C7: CL | D7: body | E7: Leading militaries often struggle to adopt organisationally disruptive innovations | F7: causal | G7: W3;W4 | H7: W3 | I7: to_W1W2 | J7: P4 | K7: NA | L7: NA | M7: NA | N7: C001 | O7: supporting | P7: =IF(OR(F7="",H7="",J7=""),"",J7&"|"&F7&"|"&IF(H7="W3","W3_"&IF(I7="","unknown",I7),H7)) -> P4|causal|W3_to_W1W2 | Q7: =IF(P7="","",IFERROR(IF(AND(H7="W7",OR(F7="causal",F7="predictive")),IF(AND(OR(K7=1,K7="1"),OR(L7=1,L7="1"),OR(M7=1,M7="1")),"adequate","partial"),IF(AND(H7="W4",F7="predictive",OR(J7="P2",J7="P3",J7="P4")),IF(OR(U7=1,U7="1"),"adequate","partial"),INDEX(Fit_Matrix!$B:$B,MATCH(P7,Fit_Matrix!$A:$A,0)))),"CHECK KEY")) -> adequate | R7: adequate | T7: Royal Navy carrier case via Horowitz 2010 | U7: NA | V7: NA | W7: NA | X7: NA | Y7: 1 | Z7: NA | AA7: =IF(A7="","",IF(AND(J7="P4",F7="causal"),"P4-CAUSAL","")) -> P4-CAUSAL
A8: K0007 | B8: A002 | C8: CL | D8: body (character of war) | E8: Narrow AI systems have the potential to increase the speed with which countries can fight | F8: predictive | G8: W6;W4 | H8: W6 | J8: P4 | K8: 0 | L8: 1 | M8: 0 | N8: C002 | P8: =IF(OR(F8="",H8="",J8=""),"",J8&"|"&F8&"|"&IF(H8="W3","W3_"&IF(I8="","unknown",I8),H8)) -> P4|predictive|W6 | Q8: =IF(P8="","",IFERROR(IF(AND(H8="W7",OR(F8="causal",F8="predictive")),IF(AND(OR(K8=1,K8="1"),OR(L8=1,L8="1"),OR(M8=1,M8="1")),"adequate","partial"),IF(AND(H8="W4",F8="predictive",OR(J8="P2",J8="P3",J8="P4")),IF(OR(U8=1,U8="1"),"adequate","partial"),INDEX(Fit_Matrix!$B:$B,MATCH(P8,Fit_Matrix!$A:$A,0)))),"CHECK KEY")) -> partial | R8: partial | T8: warrant: Work speech, Allen & Husain; 'potential' | U8: NA | V8: NA | W8: NA | X8: NA | Y8: NA | Z8: NA | AA8: =IF(A8="","",IF(AND(J8="P4",F8="causal"),"P4-CAUSAL",""))
A9: K0008 | B9: A002 | C9: CL | D9: conclusion | E9: Major military powers will likely face security dilemmas over AI development regardless of diffusion speed | F9: predictive | G9: W5 | H9: W5 | J9: P4 | K9: 1 | L9: 1 | M9: 0 | P9: =IF(OR(F9="",H9="",J9=""),"",J9&"|"&F9&"|"&IF(H9="W3","W3_"&IF(I9="","unknown",I9),H9)) -> P4|predictive|W5 | Q9: =IF(P9="","",IFERROR(IF(AND(H9="W7",OR(F9="causal",F9="predictive")),IF(AND(OR(K9=1,K9="1"),OR(L9=1,L9="1"),OR(M9=1,M9="1")),"adequate","partial"),IF(AND(H9="W4",F9="predictive",OR(J9="P2",J9="P3",J9="P4")),IF(OR(U9=1,U9="1"),"adequate","partial"),INDEX(Fit_Matrix!$B:$B,MATCH(P9,Fit_Matrix!$A:$A,0)))),"CHECK KEY")) -> partial | R9: partial | T9: deduction from Jervis; both scenarios covered | U9: NA | V9: NA | W9: NA | X9: NA | Y9: NA | Z9: NA | AA9: =IF(A9="","",IF(AND(J9="P4",F9="causal"),"P4-CAUSAL",""))
A10: K0009 | B10: A002 | C10: CL | D10: conclusion | E10: US military rhetoric on AI has not caught up to reality in spending | F10: descriptive | G10: W3;W2 | H10: W3 | I10: to_W4W8 | J10: P4 | K10: NA | L10: NA | M10: NA | P10: =IF(OR(F10="",H10="",J10=""),"",J10&"|"&F10&"|"&IF(H10="W3","W3_"&IF(I10="","unknown",I10),H10)) -> P4|descriptive|W3_to_W4W8 | Q10: =IF(P10="","",IFERROR(IF(AND(H10="W7",OR(F10="causal",F10="predictive")),IF(AND(OR(K10=1,K10="1"),OR(L10=1,L10="1"),OR(M10=1,M10="1")),"adequate","partial"),IF(AND(H10="W4",F10="predictive",OR(J10="P2",J10="P3",J10="P4")),IF(OR(U10=1,U10="1"),"adequate","partial"),INDEX(Fit_Matrix!$B:$B,MATCH(P10,Fit_Matrix!$A:$A,0)))),"CHECK KEY")) -> partial | R10: partial | T10: single programme decision (MQ-25) via news source | U10: NA | V10: NA | W10: NA | X10: NA | Y10: 0 | Z10: NA | AA10: =IF(A10="","",IF(AND(J10="P4",F10="causal"),"P4-CAUSAL",""))
A11: K0010 | B11: A002 | C11: CL | D11: conclusion | E11: China is spending much more than the US on AI research and producing more deep-learning papers | F11: descriptive | G11: W3 | H11: W3 | I11: to_W4W8 | J11: P4 | K11: NA | L11: NA | M11: NA | P11: =IF(OR(F11="",H11="",J11=""),"",J11&"|"&F11&"|"&IF(H11="W3","W3_"&IF(I11="","unknown",I11),H11)) -> P4|descriptive|W3_to_W4W8 | Q11: =IF(P11="","",IFERROR(IF(AND(H11="W7",OR(F11="causal",F11="predictive")),IF(AND(OR(K11=1,K11="1"),OR(L11=1,L11="1"),OR(M11=1,M11="1")),"adequate","partial"),IF(AND(H11="W4",F11="predictive",OR(J11="P2",J11="P3",J11="P4")),IF(OR(U11=1,U11="1"),"adequate","partial"),INDEX(Fit_Matrix!$B:$B,MATCH(P11,Fit_Matrix!$A:$A,0)))),"CHECK KEY")) -> partial | R11: partial | T11: news source (NYT), no underlying dataset cited | U11: NA | V11: NA | W11: NA | X11: NA | Y11: 0 | Z11: NA | AA11: =IF(A11="","",IF(AND(J11="P4",F11="causal"),"P4-CAUSAL",""))
A12: K0011 | B12: A002 | C12: CL | D12: abstract | E12: AI's still-emerging development makes it harder to assess than many technological changes because adoption decisions are in their infancy | F12: conceptual | G12: W5 | H12: W5 | J12: P4 | K12: NA | L12: NA | M12: NA | P12: =IF(OR(F12="",H12="",J12=""),"",J12&"|"&F12&"|"&IF(H12="W3","W3_"&IF(I12="","unknown",I12),H12)) -> P4|conceptual|W5 | Q12: =IF(P12="","",IFERROR(IF(AND(H12="W7",OR(F12="causal",F12="predictive")),IF(AND(OR(K12=1,K12="1"),OR(L12=1,L12="1"),OR(M12=1,M12="1")),"adequate","partial"),IF(AND(H12="W4",F12="predictive",OR(J12="P2",J12="P3",J12="P4")),IF(OR(U12=1,U12="1"),"adequate","partial"),INDEX(Fit_Matrix!$B:$B,MATCH(P12,Fit_Matrix!$A:$A,0)))),"CHECK KEY")) -> adequate | R12: adequate | U12: NA | V12: NA | W12: NA | X12: NA | Y12: NA | Z12: NA | AA12: =IF(A12="","",IF(AND(J12="P4",F12="causal"),"P4-CAUSAL",""))
A13: K0012 | B13: A003 | C13: CL | D13: abstract | E13: The data- and resource-intensive nature of AI creates barriers to burden-sharing and interoperability that can hamper multinational operations | F13: causal | G13: W5;W4;W6 | H13: W5 | J13: P4 | K13: 1 | L13: 1 | M13: 0 | N13: C006 | P13: =IF(OR(F13="",H13="",J13=""),"",J13&"|"&F13&"|"&IF(H13="W3","W3_"&IF(I13="","unknown",I13),H13)) -> P4|causal|W5 | Q13: =IF(P13="","",IFERROR(IF(AND(H13="W7",OR(F13="causal",F13="predictive")),IF(AND(OR(K13=1,K13="1"),OR(L13=1,L13="1"),OR(M13=1,M13="1")),"adequate","partial"),IF(AND(H13="W4",F13="predictive",OR(J13="P2",J13="P3",J13="P4")),IF(OR(U13=1,U13="1"),"adequate","partial"),INDEX(Fit_Matrix!$B:$B,MATCH(P13,Fit_Matrix!$A:$A,0)))),"CHECK KEY")) -> partial | R13: partial | T13: causal-future; scope: 'more vexing for coalitions lacking formalization'; Kosovo PGM analogy; Shanahan quote. P4 causal flagged | U13: NA | V13: NA | W13: NA | X13: NA | Y13: NA | Z13: NA | AA13: =IF(A13="","",IF(AND(J13="P4",F13="causal"),"P4-CAUSAL","")) -> P4-CAUSAL
A14: K0013 | B14: A003 | C14: CL | D14: abstract | E14: By accelerating the speed of combat, AI can strain the processes allies use to make decisions | F14: predictive | G14: W4;W6 | H14: W4 | J14: P4 | K14: 0 | L14: 1 | M14: 0 | N14: C002 | P14: =IF(OR(F14="",H14="",J14=""),"",J14&"|"&F14&"|"&IF(H14="W3","W3_"&IF(I14="","unknown",I14),H14)) -> P4|predictive|W4 | Q14: =IF(P14="","",IFERROR(IF(AND(H14="W7",OR(F14="causal",F14="predictive")),IF(AND(OR(K14=1,K14="1"),OR(L14=1,L14="1"),OR(M14=1,M14="1")),"adequate","partial"),IF(AND(H14="W4",F14="predictive",OR(J14="P2",J14="P3",J14="P4")),IF(OR(U14=1,U14="1"),"adequate","partial"),INDEX(Fit_Matrix!$B:$B,MATCH(P14,Fit_Matrix!$A:$A,0)))),"CHECK KEY")) -> adequate | R14: adequate | T14: developed analogy: NATO 1978 warning time, BMD pre-delegation (full subsection) | U14: 1 | V14: NA | W14: NA | X14: NA | Y14: NA | Z14: NA | AA14: =IF(A14="","",IF(AND(J14="P4",F14="causal"),"P4-CAUSAL",""))
A15: K0014 | B15: A003 | C15: CL | D15: introduction | E15: Adversaries can use AI-enabled deception (deepfakes, data poisoning) to interfere with alliance command and control and heighten mistrust | F15: predictive | G15: W4;W3 | H15: W4 | J15: P4 | K15: 0 | L15: 1 | M15: 0 | N15: C008 | P15: =IF(OR(F15="",H15="",J15=""),"",J15&"|"&F15&"|"&IF(H15="W3","W3_"&IF(I15="","unknown",I15),H15)) -> P4|predictive|W4 | Q15: =IF(P15="","",IFERROR(IF(AND(H15="W7",OR(F15="causal",F15="predictive")),IF(AND(OR(K15=1,K15="1"),OR(L15=1,L15="1"),OR(M15=1,M15="1")),"adequate","partial"),IF(AND(H15="W4",F15="predictive",OR(J15="P2",J15="P3",J15="P4")),IF(OR(U15=1,U15="1"),"adequate","partial"),INDEX(Fit_Matrix!$B:$B,MATCH(P15,Fit_Matrix!$A:$A,0)))),"CHECK KEY")) -> adequate | R15: adequate | T15: analogy to WWII deception; 2019 voice-clone fraud as illustration; full subsection | U15: 1 | V15: NA | W15: NA | X15: NA | Y15: NA | Z15: NA | AA15: =IF(A15="","",IF(AND(J15="P4",F15="causal"),"P4-CAUSAL",""))
A16: K0015 | B16: A003 | C16: CL | D16: body | E16: Not all states will develop military AI at the same rate; uneven distribution creates AI haves and have-nots within alliances | F16: predictive | G16: W3;W5 | H16: W3 | I16: to_W1W2 | J16: P4 | K16: 0 | L16: 0 | M16: 0 | N16: C006 | P16: =IF(OR(F16="",H16="",J16=""),"",J16&"|"&F16&"|"&IF(H16="W3","W3_"&IF(I16="","unknown",I16),H16)) -> P4|predictive|W3_to_W1W2 | Q16: =IF(P16="","",IFERROR(IF(AND(H16="W7",OR(F16="causal",F16="predictive")),IF(AND(OR(K16=1,K16="1"),OR(L16=1,L16="1"),OR(M16=1,M16="1")),"adequate","partial"),IF(AND(H16="W4",F16="predictive",OR(J16="P2",J16="P3",J16="P4")),IF(OR(U16=1,U16="1"),"adequate","partial"),INDEX(Fit_Matrix!$B:$B,MATCH(P16,Fit_Matrix!$A:$A,0)))),"CHECK KEY")) -> adequate | R16: adequate | T16: Oxford Insights readiness index (grey but data-based); asserted without hedge ('will') | U16: NA | V16: unknown | W16: unknown | X16: unknown | Y16: 0 | Z16: NA | AA16: =IF(A16="","",IF(AND(J16="P4",F16="causal"),"P4-CAUSAL",""))
A17: K0016 | B17: A003 | C17: CL | D17: body | E17: Public opposition among allied populations may lead governments to restrict use of AI-enabled military systems | F17: predictive | G17: W3;W5 | H17: W3 | I17: to_W1W2 | J17: P4 | K17: 1 | L17: 1 | M17: 0 | P17: =IF(OR(F17="",H17="",J17=""),"",J17&"|"&F17&"|"&IF(H17="W3","W3_"&IF(I17="","unknown",I17),H17)) -> P4|predictive|W3_to_W1W2 | Q17: =IF(P17="","",IFERROR(IF(AND(H17="W7",OR(F17="causal",F17="predictive")),IF(AND(OR(K17=1,K17="1"),OR(L17=1,L17="1"),OR(M17=1,M17="1")),"adequate","partial"),IF(AND(H17="W4",F17="predictive",OR(J17="P2",J17="P3",J17="P4")),IF(OR(U17=1,U17="1"),"adequate","partial"),INDEX(Fit_Matrix!$B:$B,MATCH(P17,Fit_Matrix!$A:$A,0)))),"CHECK KEY")) -> adequate | R17: adequate | T17: Ipsos 2019 survey; scope: South Korea, Germany | U17: NA | V17: unknown | W17: unknown | X17: unknown | Y17: 0 | Z17: NA | AA17: =IF(A17="","",IF(AND(J17="P4",F17="causal"),"P4-CAUSAL",""))
A18: K0017 | B18: A003 | C18: CL | D18: body | E18: Cross-national variation in trust in AI will make decision-makers from some states more reluctant to rely on AI-enabled systems | F18: predictive | G18: W3;W5 | H18: W3 | I18: to_W1W2 | J18: P4 | K18: 0 | L18: 1 | M18: 0 | P18: =IF(OR(F18="",H18="",J18=""),"",J18&"|"&F18&"|"&IF(H18="W3","W3_"&IF(I18="","unknown",I18),H18)) -> P4|predictive|W3_to_W1W2 | Q18: =IF(P18="","",IFERROR(IF(AND(H18="W7",OR(F18="causal",F18="predictive")),IF(AND(OR(K18=1,K18="1"),OR(L18=1,L18="1"),OR(M18=1,M18="1")),"adequate","partial"),IF(AND(H18="W4",F18="predictive",OR(J18="P2",J18="P3",J18="P4")),IF(OR(U18=1,U18="1"),"adequate","partial"),INDEX(Fit_Matrix!$B:$B,MATCH(P18,Fit_Matrix!$A:$A,0)))),"CHECK KEY")) -> adequate | R18: adequate | T18: Ipsos 2018 survey | U18: NA | V18: unknown | W18: unknown | X18: unknown | Y18: 0 | Z18: NA | AA18: =IF(A18="","",IF(AND(J18="P4",F18="causal"),"P4-CAUSAL",""))
A19: K0018 | B19: A003 | C19: CL | D19: body (way forward) | E19: Pre-delegation of authority to lower-level commanders can help alliances respond to machine-speed operations | F19: normative | G19: W4 | H19: W4 | J19: P4 | K19: NA | L19: NA | M19: NA | P19: =IF(OR(F19="",H19="",J19=""),"",J19&"|"&F19&"|"&IF(H19="W3","W3_"&IF(I19="","unknown",I19),H19)) -> P4|normative|W4 | Q19: =IF(P19="","",IFERROR(IF(AND(H19="W7",OR(F19="causal",F19="predictive")),IF(AND(OR(K19=1,K19="1"),OR(L19=1,L19="1"),OR(M19=1,M19="1")),"adequate","partial"),IF(AND(H19="W4",F19="predictive",OR(J19="P2",J19="P3",J19="P4")),IF(OR(U19=1,U19="1"),"adequate","partial"),INDEX(Fit_Matrix!$B:$B,MATCH(P19,Fit_Matrix!$A:$A,0)))),"CHECK KEY")) -> partial | R19: partial | T19: empirical premise warranted by NATO 1978 and BMD analogies; normative inference not coded | U19: NA | V19: NA | W19: NA | X19: NA | Y19: NA | Z19: NA | AA19: =IF(A19="","",IF(AND(J19="P4",F19="causal"),"P4-CAUSAL",""))
A20: K0019 | B20: A003 | C20: CL | D20: conclusion | E20: States that master AI integration may gain influence within alliances even if conventionally weaker | F20: predictive | G20: W4 | H20: W4 | J20: P4 | K20: 0 | L20: 1 | M20: 0 | P20: =IF(OR(F20="",H20="",J20=""),"",J20&"|"&F20&"|"&IF(H20="W3","W3_"&IF(I20="","unknown",I20),H20)) -> P4|predictive|W4 | Q20: =IF(P20="","",IFERROR(IF(AND(H20="W7",OR(F20="causal",F20="predictive")),IF(AND(OR(K20=1,K20="1"),OR(L20=1,L20="1"),OR(M20=1,M20="1")),"adequate","partial"),IF(AND(H20="W4",F20="predictive",OR(J20="P2",J20="P3",J20="P4")),IF(OR(U20=1,U20="1"),"adequate","partial"),INDEX(Fit_Matrix!$B:$B,MATCH(P20,Fit_Matrix!$A:$A,0)))),"CHECK KEY")) -> partial | R20: partial | T20: single-paragraph analogy (Estonia, cyber); w4_developed=0 so the P2-P4 full-section rule returns partial without an override | U20: 0 | V20: NA | W20: NA | X20: NA | Y20: NA | Z20: NA | AA20: =IF(A20="","",IF(AND(J20="P4",F20="causal"),"P4-CAUSAL",""))
A21: K0020 | B21: A003 | C21: CL | D21: introduction | E21: Most scholarly work on alliances has overlooked the effects of specific technologies, with the exception of nuclear weapons | F21: descriptive | G21: W2 | H21: W2 | J21: P4 | K21: NA | L21: NA | M21: NA | P21: =IF(OR(F21="",H21="",J21=""),"",J21&"|"&F21&"|"&IF(H21="W3","W3_"&IF(I21="","unknown",I21),H21)) -> P4|descriptive|W2 | Q21: =IF(P21="","",IFERROR(IF(AND(H21="W7",OR(F21="causal",F21="predictive")),IF(AND(OR(K21=1,K21="1"),OR(L21=1,L21="1"),OR(M21=1,M21="1")),"adequate","partial"),IF(AND(H21="W4",F21="predictive",OR(J21="P2",J21="P3",J21="P4")),IF(OR(U21=1,U21="1"),"adequate","partial"),INDEX(Fit_Matrix!$B:$B,MATCH(P21,Fit_Matrix!$A:$A,0)))),"CHECK KEY")) -> adequate | R21: adequate | T21: author's own literature review (footnotes 12-15) | U21: NA | V21: NA | W21: NA | X21: NA | Y21: NA | Z21: NA | AA21: =IF(A21="","",IF(AND(J21="P4",F21="causal"),"P4-CAUSAL",""))
A22: K0021 | B22: A003 | C22: CL | D22: conclusion | E22: This article offers a framework for future hypothesis testing | F22: conceptual | G22: W5;W7 | H22: W7 | J22: P4 | K22: NA | L22: NA | M22: NA | P22: =IF(OR(F22="",H22="",J22=""),"",J22&"|"&F22&"|"&IF(H22="W3","W3_"&IF(I22="","unknown",I22),H22)) -> P4|conceptual|W7 | Q22: =IF(P22="","",IFERROR(IF(AND(H22="W7",OR(F22="causal",F22="predictive")),IF(AND(OR(K22=1,K22="1"),OR(L22=1,L22="1"),OR(M22=1,M22="1")),"adequate","partial"),IF(AND(H22="W4",F22="predictive",OR(J22="P2",J22="P3",J22="P4")),IF(OR(U22=1,U22="1"),"adequate","partial"),INDEX(Fit_Matrix!$B:$B,MATCH(P22,Fit_Matrix!$A:$A,0)))),"CHECK KEY")) -> adequate | R22: adequate | T22: explicit self-declaration of status; positive example for Section 4.6 | U22: NA | V22: NA | W22: NA | X22: NA | Y22: NA | Z22: NA | AA22: =IF(A22="","",IF(AND(J22="P4",F22="causal"),"P4-CAUSAL",""))
P23: =IF(OR(F23="",H23="",J23=""),"",J23&"|"&F23&"|"&IF(H23="W3","W3_"&IF(I23="","unknown",I23),H23)) | Q23: =IF(P23="","",IFERROR(IF(AND(H23="W7",OR(F23="causal",F23="predictive")),IF(AND(OR(K23=1,K23="1"),OR(L23=1,L23="1"),OR(M23=1,M23="1")),"adequate","partial"),IF(AND(H23="W4",F23="predictive",OR(J23="P2",J23="P3",J23="P4")),IF(OR(U23=1,U23="1"),"adequate","partial"),INDEX(Fit_Matrix!$B:$B,MATCH(P23,Fit_Matrix!$A:$A,0)))),"CHECK KEY")) | AA23: =IF(A23="","",IF(AND(J23="P4",F23="causal"),"P4-CAUSAL",""))
P24: =IF(OR(F24="",H24="",J24=""),"",J24&"|"&F24&"|"&IF(H24="W3","W3_"&IF(I24="","unknown",I24),H24)) | Q24: =IF(P24="","",IFERROR(IF(AND(H24="W7",OR(F24="causal",F24="predictive")),IF(AND(OR(K24=1,K24="1"),OR(L24=1,L24="1"),OR(M24=1,M24="1")),"adequate","partial"),IF(AND(H24="W4",F24="predictive",OR(J24="P2",J24="P3",J24="P4")),IF(OR(U24=1,U24="1"),"adequate","partial"),INDEX(Fit_Matrix!$B:$B,MATCH(P24,Fit_Matrix!$A:$A,0)))),"CHECK KEY")) | AA24: =IF(A24="","",IF(AND(J24="P4",F24="causal"),"P4-CAUSAL",""))
P25: =IF(OR(F25="",H25="",J25=""),"",J25&"|"&F25&"|"&IF(H25="W3","W3_"&IF(I25="","unknown",I25),H25)) | Q25: =IF(P25="","",IFERROR(IF(AND(H25="W7",OR(F25="causal",F25="predictive")),IF(AND(OR(K25=1,K25="1"),OR(L25=1,L25="1"),OR(M25=1,M25="1")),"adequate","partial"),IF(AND(H25="W4",F25="predictive",OR(J25="P2",J25="P3",J25="P4")),IF(OR(U25=1,U25="1"),"adequate","partial"),INDEX(Fit_Matrix!$B:$B,MATCH(P25,Fit_Matrix!$A:$A,0)))),"CHECK KEY")) | AA25: =IF(A25="","",IF(AND(J25="P4",F25="causal"),"P4-CAUSAL",""))
P26: =IF(OR(F26="",H26="",J26=""),"",J26&"|"&F26&"|"&IF(H26="W3","W3_"&IF(I26="","unknown",I26),H26)) | Q26: =IF(P26="","",IFERROR(IF(AND(H26="W7",OR(F26="causal",F26="predictive")),IF(AND(OR(K26=1,K26="1"),OR(L26=1,L26="1"),OR(M26=1,M26="1")),"adequate","partial"),IF(AND(H26="W4",F26="predictive",OR(J26="P2",J26="P3",J26="P4")),IF(OR(U26=1,U26="1"),"adequate","partial"),INDEX(Fit_Matrix!$B:$B,MATCH(P26,Fit_Matrix!$A:$A,0)))),"CHECK KEY")) | AA26: =IF(A26="","",IF(AND(J26="P4",F26="causal"),"P4-CAUSAL",""))
P27: =IF(OR(F27="",H27="",J27=""),"",J27&"|"&F27&"|"&IF(H27="W3","W3_"&IF(I27="","unknown",I27),H27)) | Q27: =IF(P27="","",IFERROR(IF(AND(H27="W7",OR(F27="causal",F27="predictive")),IF(AND(OR(K27=1,K27="1"),OR(L27=1,L27="1"),OR(M27=1,M27="1")),"adequate","partial"),IF(AND(H27="W4",F27="predictive",OR(J27="P2",J27="P3",J27="P4")),IF(OR(U27=1,U27="1"),"adequate","partial"),INDEX(Fit_Matrix!$B:$B,MATCH(P27,Fit_Matrix!$A:$A,0)))),"CHECK KEY")) | AA27: =IF(A27="","",IF(AND(J27="P4",F27="causal"),"P4-CAUSAL",""))
P28: =IF(OR(F28="",H28="",J28=""),"",J28&"|"&F28&"|"&IF(H28="W3","W3_"&IF(I28="","unknown",I28),H28)) | Q28: =IF(P28="","",IFERROR(IF(AND(H28="W7",OR(F28="causal",F28="predictive")),IF(AND(OR(K28=1,K28="1"),OR(L28=1,L28="1"),OR(M28=1,M28="1")),"adequate","partial"),IF(AND(H28="W4",F28="predictive",OR(J28="P2",J28="P3",J28="P4")),IF(OR(U28=1,U28="1"),"adequate","partial"),INDEX(Fit_Matrix!$B:$B,MATCH(P28,Fit_Matrix!$A:$A,0)))),"CHECK KEY")) | AA28: =IF(A28="","",IF(AND(J28="P4",F28="causal"),"P4-CAUSAL",""))
P29: =IF(OR(F29="",H29="",J29=""),"",J29&"|"&F29&"|"&IF(H29="W3","W3_"&IF(I29="","unknown",I29),H29)) | Q29: =IF(P29="","",IFERROR(IF(AND(H29="W7",OR(F29="causal",F29="predictive")),IF(AND(OR(K29=1,K29="1"),OR(L29=1,L29="1"),OR(M29=1,M29="1")),"adequate","partial"),IF(AND(H29="W4",F29="predictive",OR(J29="P2",J29="P3",J29="P4")),IF(OR(U29=1,U29="1"),"adequate","partial"),INDEX(Fit_Matrix!$B:$B,MATCH(P29,Fit_Matrix!$A:$A,0)))),"CHECK KEY")) | AA29: =IF(A29="","",IF(AND(J29="P4",F29="causal"),"P4-CAUSAL",""))
P30: =IF(OR(F30="",H30="",J30=""),"",J30&"|"&F30&"|"&IF(H30="W3","W3_"&IF(I30="","unknown",I30),H30)) | Q30: =IF(P30="","",IFERROR(IF(AND(H30="W7",OR(F30="causal",F30="predictive")),IF(AND(OR(K30=1,K30="1"),OR(L30=1,L30="1"),OR(M30=1,M30="1")),"adequate","partial"),IF(AND(H30="W4",F30="predictive",OR(J30="P2",J30="P3",J30="P4")),IF(OR(U30=1,U30="1"),"adequate","partial"),INDEX(Fit_Matrix!$B:$B,MATCH(P30,Fit_Matrix!$A:$A,0)))),"CHECK KEY")) | AA30: =IF(A30="","",IF(AND(J30="P4",F30="causal"),"P4-CAUSAL",""))
P31: =IF(OR(F31="",H31="",J31=""),"",J31&"|"&F31&"|"&IF(H31="W3","W3_"&IF(I31="","unknown",I31),H31)) | Q31: =IF(P31="","",IFERROR(IF(AND(H31="W7",OR(F31="causal",F31="predictive")),IF(AND(OR(K31=1,K31="1"),OR(L31=1,L31="1"),OR(M31=1,M31="1")),"adequate","partial"),IF(AND(H31="W4",F31="predictive",OR(J31="P2",J31="P3",J31="P4")),IF(OR(U31=1,U31="1"),"adequate","partial"),INDEX(Fit_Matrix!$B:$B,MATCH(P31,Fit_Matrix!$A:$A,0)))),"CHECK KEY")) | AA31: =IF(A31="","",IF(AND(J31="P4",F31="causal"),"P4-CAUSAL",""))
P32: =IF(OR(F32="",H32="",J32=""),"",J32&"|"&F32&"|"&IF(H32="W3","W3_"&IF(I32="","unknown",I32),H32)) | Q32: =IF(P32="","",IFERROR(IF(AND(H32="W7",OR(F32="causal",F32="predictive")),IF(AND(OR(K32=1,K32="1"),OR(L32=1,L32="1"),OR(M32=1,M32="1")),"adequate","partial"),IF(AND(H32="W4",F32="predictive",OR(J32="P2",J32="P3",J32="P4")),IF(OR(U32=1,U32="1"),"adequate","partial"),INDEX(Fit_Matrix!$B:$B,MATCH(P32,Fit_Matrix!$A:$A,0)))),"CHECK KEY")) | AA32: =IF(A32="","",IF(AND(J32="P4",F32="causal"),"P4-CAUSAL",""))
P33: =IF(OR(F33="",H33="",J33=""),"",J33&"|"&F33&"|"&IF(H33="W3","W3_"&IF(I33="","unknown",I33),H33)) | Q33: =IF(P33="","",IFERROR(IF(AND(H33="W7",OR(F33="causal",F33="predictive")),IF(AND(OR(K33=1,K33="1"),OR(L33=1,L33="1"),OR(M33=1,M33="1")),"adequate","partial"),IF(AND(H33="W4",F33="predictive",OR(J33="P2",J33="P3",J33="P4")),IF(OR(U33=1,U33="1"),"adequate","partial"),INDEX(Fit_Matrix!$B:$B,MATCH(P33,Fit_Matrix!$A:$A,0)))),"CHECK KEY")) | AA33: =IF(A33="","",IF(AND(J33="P4",F33="causal"),"P4-CAUSAL",""))
P34: =IF(OR(F34="",H34="",J34=""),"",J34&"|"&F34&"|"&IF(H34="W3","W3_"&IF(I34="","unknown",I34),H34)) | Q34: =IF(P34="","",IFERROR(IF(AND(H34="W7",OR(F34="causal",F34="predictive")),IF(AND(OR(K34=1,K34="1"),OR(L34=1,L34="1"),OR(M34=1,M34="1")),"adequate","partial"),IF(AND(H34="W4",F34="predictive",OR(J34="P2",J34="P3",J34="P4")),IF(OR(U34=1,U34="1"),"adequate","partial"),INDEX(Fit_Matrix!$B:$B,MATCH(P34,Fit_Matrix!$A:$A,0)))),"CHECK KEY")) | AA34: =IF(A34="","",IF(AND(J34="P4",F34="causal"),"P4-CAUSAL",""))
... P5000: =IF(OR(F5000="",H5000="",J5000=""),"",J5000&"|"&F5000&"|"&IF(H5000="W3","W3_"&IF(I5000="","unknown",I5000),H5000)) | Q5000: =IF(P5000="","",IFERROR(IF(AND(H5000="W7",OR(F5000="causal",F5000="predictive")),IF(AND(OR(K5000=1,K5000="1"),OR(L5000=1,L5000="1"),OR(M5000=1,M5000="1")),"adequate","partial"),IF(AND(H5000="W4",F5000="predictive",OR(J5000="P2",J5000="P3",J5000="P4")),IF(OR(U5000=1,U5000="1"),"adequate","partial"),INDEX(Fit_Matrix!$B:$B,MATCH(P5000,Fit_Matrix!$A:$A,0)))),"CHECK KEY")) | AA5000: =IF(A5000="","",IF(AND(J5000="P4",F5000="causal"),"P4-CAUSAL",""))

Sheet Change_Log
A1: date | B1: change | C1: reason | D1: stage | E1: approved_by
A2: 2026-09-07 | B2: Pilot rows K0001-K0021 entered by coder CL (Claude) on two open-access TNSR articles | C2: Pilot only; not protocol data; TNSR indexing status unverified | D2: pre-freeze pilot | E2: user
A3: 2026-09-10 | B3: Deposit target changed from OSF Registries to a public Git repository with a Zenodo-archived release; protocol section 15 added | C3: Investigator preference; equivalent public time-stamping and DOI | D3: pre-freeze | E3: MK
A4: 2026-09-10 | B4: fit_computed rewritten: indicator test now accepts numeric or text 0/1 | C4: Indicators were stored as text, so AND(K=1,L=1,M=1) was always FALSE in Excel and no claim could ever score adequate under the W7 rule. Latent: the pilot had no 3/3 claim, so it never surfaced | D4: pre-freeze | E4: MK
A5: 2026-09-10 | B5: scope_conditions, conjectural_status and falsifier converted from text to numbers | C5: Same defect, fixed at the data layer as well as the formula layer | D5: pre-freeze | E5: MK
A6: 2026-09-10 | B6: Column w4_developed added; Fit_Matrix P2/P3/P4|predictive|W4 reset to partial | C6: Appendix A.5 requires the analogy to be developed over a full section, but the matrix granted adequate unconditionally and the condition had no input column | D6: pre-freeze | E6: MK
A7: 2026-09-10 | B7: Columns orig_scope_conditions, orig_conjectural_status, orig_falsifier added | C7: Table 4, RQ3 and H2 compare originating and citing text; only citing-text indicators existed, so the comparison could not be computed | D7: pre-freeze | E7: MK
A8: 2026-09-10 | B8: Column w3_source_peer_reviewed added | C8: Pilot note item 2: sub-code turns on whether the source carries data; peer-review status recorded separately | D8: pre-freeze | E8: MK
A9: 2026-09-10 | B9: Column secondary_claim_type added | C9: Appendix A.3 requires causal and predictive to be coded together, which a single claim_type column could not represent | D9: pre-freeze | E9: MK
A10: 2026-09-10 | B10: Column p4_causal_flag added (derived) | C10: Pilot note item 5: the P4 causal flag was free text in notes and could not be tabulated | D10: pre-freeze | E10: MK
A11: 2026-09-10 | B11: Licence set: CC BY 4.0 for text, protocol, codebook and data; MIT for the analysis script | C11: Required before deposit; matches the licence recorded on the Zenodo record | D11: pre-freeze | E11: MK
A12: 2026-09-10 | B12: Deposit v1 made: tag protocol-freeze, commit f50707436317a533fe9fa9a9a5f9e68213671e0b, DOI 10.5281/zenodo.22696658 | C12: Recorded as a pre-freeze snapshot, NOT as the pre-registration. At that commit the sampling seed (protocol s.6) was unfilled and the codebook decisions in protocol s.16 were open. Superseded by deposit v2, not deleted | D12: pre-freeze | E12: MK
... A14: 2026-09-10 | B14: Snapshot 2 deposited: tag protocol-freeze-v1, commit 2e709266a96dba93122dd7ee0c557b64324d79c8, DOI 10.5281/zenodo.22697017 | C14: Second dated snapshot, taken after working notes were moved out of the deposit and the search contingency was folded into protocol s.3. Not the pre-registration: protocol s.16 gate still open. The freeze will be tagged preregistration-v1 | D14: pre-freeze | E14: MK

Sheet Summary
A1: Live summary (formulas only)
A3: Total claims | B3: =COUNTA(Claims!A2:A5000) -> 21
A4: Total articles | B4: =COUNTA(Articles!A2:A2000) -> 2
A6: By claim type | B6: n | C6: share
A7: descriptive | B7: =COUNTIF(Claims!F2:F5000,"descriptive") -> 4 | C7: =IF($B$3=0,0,B7/$B$3) -> 0.19047619
A8: conceptual | B8: =COUNTIF(Claims!F2:F5000,"conceptual") -> 3 | C8: =IF($B$3=0,0,B8/$B$3) -> 0.14285714
A9: causal | B9: =COUNTIF(Claims!F2:F5000,"causal") -> 3 | C9: =IF($B$3=0,0,B9/$B$3) -> 0.14285714
A10: predictive | B10: =COUNTIF(Claims!F2:F5000,"predictive") -> 10 | C10: =IF($B$3=0,0,B10/$B$3) -> 0.47619048
A11: normative | B11: =COUNTIF(Claims!F2:F5000,"normative") -> 1 | C11: =IF($B$3=0,0,B11/$B$3) -> 0.047619048
A12: other | B12: =COUNTIF(Claims!F2:F5000,"other") -> 0 | C12: =IF($B$3=0,0,B12/$B$3) -> 0
A14: By primary warrant
A15: W1 | B15: =COUNTIF(Claims!H2:H5000,"W1") -> 0 | C15: =IF($B$3=0,0,B15/$B$3) -> 0
A16: W2 | B16: =COUNTIF(Claims!H2:H5000,"W2") -> 1 | C16: =IF($B$3=0,0,B16/$B$3) -> 0.047619048
A17: W3 | B17: =COUNTIF(Claims!H2:H5000,"W3") -> 7 | C17: =IF($B$3=0,0,B17/$B$3) -> 0.33333333
A18: W4 | B18: =COUNTIF(Claims!H2:H5000,"W4") -> 5 | C18: =IF($B$3=0,0,B18/$B$3) -> 0.23809524
A19: W5 | B19: =COUNTIF(Claims!H2:H5000,"W5") -> 3 | C19: =IF($B$3=0,0,B19/$B$3) -> 0.14285714
A20: W6 | B20: =COUNTIF(Claims!H2:H5000,"W6") -> 2 | C20: =IF($B$3=0,0,B20/$B$3) -> 0.095238095
A21: W7 | B21: =COUNTIF(Claims!H2:H5000,"W7") -> 3 | C21: =IF($B$3=0,0,B21/$B$3) -> 0.14285714
A22: W8 | B22: =COUNTIF(Claims!H2:H5000,"W8") -> 0 | C22: =IF($B$3=0,0,B22/$B$3) -> 0
A24: By fit (final)
A25: adequate | B25: =COUNTIF(Claims!R2:R5000,"adequate") -> 11 | C25: =IF($B$3=0,0,B25/$B$3) -> 0.52380952
A26: partial | B26: =COUNTIF(Claims!R2:R5000,"partial") -> 10 | C26: =IF($B$3=0,0,B26/$B$3) -> 0.47619048
A27: inadequate | B27: =COUNTIF(Claims!R2:R5000,"inadequate") -> 0 | C27: =IF($B$3=0,0,B27/$B$3) -> 0
A29: Declared-forecast indicators (predictive+causal-future)
A30: claims eligible (not NA) | B30: =COUNTIF(Claims!K2:K5000,"0")+COUNTIF(Claims!K2:K5000,"1") -> 11
A31: scope conditions =1 | B31: =COUNTIF(Claims!K2:K5000,"1") -> 5 | C31: =IF($B$30=0,0,B31/$B$30) -> 0.45454545
A32: conjectural status =1 | B32: =COUNTIF(Claims!L2:L5000,"1") -> 10 | C32: =IF($B$30=0,0,B32/$B$30) -> 0.90909091
A33: falsifier =1 | B33: =COUNTIF(Claims!M2:M5000,"1") -> 0 | C33: =IF($B$30=0,0,B33/$B$30) -> 0
A34: all three =1 (declared forecasts) | B34: =COUNTIFS(Claims!K2:K5000,"1",Claims!L2:L5000,"1",Claims!M2:M5000,"1") -> 0 | C34: =IF($B$30=0,0,B34/$B$30) -> 0
A35: none =1 (circulated findings) | B35: =COUNTIFS(Claims!K2:K5000,"0",Claims!L2:L5000,"0",Claims!M2:M5000,"0") -> 1 | C35: =IF($B$30=0,0,B35/$B$30) -> 0.090909091
A37: Fit key errors (CHECK KEY) | B37: =COUNTIF(Claims!Q2:Q5000,"CHECK KEY") -> 0
A39: Transmission (Table 4): originating vs citing text, W3 claims
A40: scope conditions: originating =1 / citing =1 / pairs known | B40: =COUNTIFS(Claims!V2:V5000,"1",Claims!H2:H5000,"W3") -> 0 | C40: =COUNTIFS(Claims!K2:K5000,"1",Claims!H2:H5000,"W3") -> 1
A41: conjectural status: originating =1 / citing =1 / pairs known | B41: =COUNTIFS(Claims!W2:W5000,"1",Claims!H2:H5000,"W3") -> 0 | C41: =COUNTIFS(Claims!L2:L5000,"1",Claims!H2:H5000,"W3") -> 2
A42: falsifier: originating =1 / citing =1 / pairs known | B42: =COUNTIFS(Claims!X2:X5000,"1",Claims!H2:H5000,"W3") -> 0 | C42: =COUNTIFS(Claims!M2:M5000,"1",Claims!H2:H5000,"W3") -> 0
A43: W3 claims with originating text retrieved (not unknown) | B43: =COUNTIFS(Claims!H2:H5000,"W3",Claims!V2:V5000,"<>unknown")-COUNTIFS(Claims!H2:H5000,"W3",Claims!V2:V5000,"NA") -> 0
A45: P4 causal claims (flagged) | B45: =COUNTIF(Claims!AA2:AA5000,"P4-CAUSAL") -> 3
A46: predictive+W4 under P2/P3/P4 with analogy developed | B46: =COUNTIFS(Claims!F2:F5000,"predictive",Claims!H2:H5000,"W4",Claims!U2:U5000,"1") -> 2
